msg="""[2024-04-18 09:06:29,662: ERROR/ForkPoolWorker-1244] Task splunk_connect_for_snmp.snmp.tasks.walk[bfa22278-ea88-41b6-b047-7025c19a61d8] raised unexpected: UnpickleableExceptionWrapper('pysnmp.error', 'PySnmpError', ('poll error: Traceback (most recent call last):\n;  File "/app/.venv/lib/python3.10/site-packages/pysnmp/carrier/asyncore/dispatch.py", line 45, in runDispatcher\n    loop(timeout or self.getTimerResolution(),\n;  File "/usr/local/lib/python3.10/asyncore.py", line 214, in loop\n    poll_fun(timeout, map)\n;  File "/usr/local/lib/python3.10/asyncore.py", line 195, in poll2\n    readwrite(obj, flags)\n;  File "/usr/local/lib/python3.10/asyncore.py", line 130, in readwrite\n    obj.handle_error()\n;  File "/usr/local/lib/python3.10/asyncore.py", line 115, in readwrite\n    obj.handle_read_event()\n;  File "/usr/local/lib/python3.10/asyncore.py", line 427, in handle_read_event\n    self.handle_read()\n;  File "/app/.venv/lib/python3.10/site-packages/pysnmp/carrier/asyncore/dgram/base.py", line 170, in handle_read\n    self._cbFun(self, transportAddress, incomingMessage)\n;  File "/app/.venv/lib/python3.10/site-packages/pysnmp/carrier/base.py", line 80, in _cbFun\n    self.__recvCallables[recvId](\n;  File "/app/.venv/lib/python3.10/site-packages/pysnmp/entity/engine.py", line 151, in __receiveMessageCbFun\n    self.msgAndPduDsp.receiveMessage(\n;  File "/app/.venv/lib/python3.10/site-packages/pysnmp/proto/rfc3412.py", line 481, in receiveMessage\n    processResponsePdu(snmpEngine, messageProcessingModel,\n;  File "/app/.venv/lib/python3.10/site-packages/pysnmp/entity/rfc3413/cmdgen.py", line 152, in processResponsePdu\n    cbFun(snmpEngine, origSendRequestHandle, None, PDU, cbCtx)\n;  File "/app/.venv/lib/python3.10/site-packages/pysnmp/entity/rfc3413/cmdgen.py", line 385, in processResponseVarBinds\n    if not cbFun(snmpEngine, sendRequestHandle, errorIndication,\n;  File "/app/.venv/lib/python3.10/site-packages/pysnmp/hlapi/asyncore/cmdgen.py", line 487, in __cbFun\n    [vbProcessor.unmakeVarBinds(snmpEngine, varBindTableRow, lookupMib) for varBindTableRow in\n;  File "/app/.venv/lib/python3.10/site-packages/pysnmp/hlapi/asyncore/cmdgen.py", line 487, in <listcomp>\n    [vbProcessor.unmakeVarBinds(snmpEngine, varBindTableRow, lookupMib) for varBindTableRow in\n;  File "/app/.venv/lib/python3.10/site-packages/pysnmp/hlapi/varbinds.py", line 46, in unmakeVarBinds\n    varBinds = [ObjectType(ObjectIdentity(x[0]), x[1]).resolveWithMib(\n;  File "/app/.venv/lib/python3.10/site-packages/pysnmp/hlapi/varbinds.py", line 46, in <listcomp>\n    varBinds = [ObjectType(ObjectIdentity(x[0]), x[1]).resolveWithMib(\n;  File "/app/.venv/lib/python3.10/site-packages/pysnmp/smi/rfc1902.py", line 850, in resolveWithMib\n    self.__args[0].resolveWithMib(mibViewController)\n;  File "/app/.venv/lib/python3.10/site-packages/pysnmp/smi/rfc1902.py", line 450, in resolveWithMib\n    self.__indices = rowNode.getIndicesFromInstId(suffix)\n;  File "/app/.venv/lib/python3.10/site-packages/pysnmp/smi/mibs/SNMPv2-SMI.py", line 1256, in getIndicesFromInstId\n    raise error.SmiError(\n;pysnmp.smi.error.SmiError: Excessive instance identifier sub-OIDs left at MibTableRow((1, 3, 6, 1, 4, 1, 2620, 1, 6, 6, 1), None): 0\ncaused by <class \'pysnmp.smi.error.SmiError\'>: Excessive instance identifier sub-OIDs left at MibTableRow((1, 3, 6, 1, 4, 1, 2620, 1, 6, 6, 1), None): 0',), 'PySnmpError(\'poll error: Traceback (most recent call last):\\n;  File "/app/.venv/lib/python3.10/site-packages/pysnmp/carrier/asyncore/dispatch.py", line 45, in runDispatcher\\n    loop(timeout or self.getTimerResolution(),\\n;  File "/usr/local/lib/python3.10/asyncore.py", line 214, in loop\\n    poll_fun(timeout, map)\\n;  File "/usr/local/lib/python3.10/asyncore.py", line 195, in poll2\\n    readwrite(obj, flags)\\n;  File "/usr/local/lib/python3.10/asyncore.py", line 130, in readwrite\\n    obj.handle_error()\\n;  File "/usr/local/lib/python3.10/asyncore.py", line 115, in readwrite\\n    obj.handle_read_event()\\n;  File "/usr/local/lib/python3.10/asyncore.py", line 427, in handle_read_event\\n    self.handle_read()\\n;  File "/app/.venv/lib/python3.10/site-packages/pysnmp/carrier/asyncore/dgram/base.py", line 170, in handle_read\\n    self._cbFun(self, transportAddress, incomingMessage)\\n;  File "/app/.venv/lib/python3.10/site-packages/pysnmp/carrier/base.py", line 80, in _cbFun\\n    self.__recvCallables[recvId](\\n;  File "/app/.venv/lib/python3.10/site-packages/pysnmp/entity/engine.py", line 151, in __receiveMessageCbFun\\n    self.msgAndPduDsp.receiveMessage(\\n;  File "/app/.venv/lib/python3.10/site-packages/pysnmp/proto/rfc3412.py", line 481, in receiveMessage\\n    processResponsePdu(snmpEngine, messageProcessingModel,\\n;  File "/app/.venv/lib/python3.10/site-packages/pysnmp/entity/rfc3413/cmdgen.py", line 152, in processResponsePdu\\n    cbFun(snmpEngine, origSendRequestHandle, None, PDU, cbCtx)\\n;  File "/app/.venv/lib/python3.10/site-packages/pysnmp/entity/rfc3413/cmdgen.py", line 385, in processResponseVarBinds\\n    if not cbFun(snmpEngine, sendRequestHandle, errorIndication,\\n;  File "/app/.venv/lib/python3.10/site-packages/pysnmp/hlapi/asyncore/cmdgen.py", line 487, in __cbFun\\n    [vbProcessor.unmakeVarBinds(snmpEngine, varBindTableRow, lookupMib) for varBindTableRow in\\n;  File "/app/.venv/lib/python3.10/site-packages/pysnmp/hlapi/asyncore/cmdgen.py", line 487, in <listcomp>\\n    [vbProcessor.unmakeVarBinds(snmpEngine, varBindTableRow, lookupMib) for varBindTableRow in\\n;  File "/app/.venv/lib/python3.10/site-packages/pysnmp/hlapi/varbinds.py", line 46, in unmakeVarBinds\\n    varBinds = [ObjectType(ObjectIdentity(x[0]), x[1]).resolveWithMib(\\n;  File "/app/.venv/lib/python3.10/site-packages/pysnmp/hlapi/varbinds.py", line 46, in <listcomp>\\n    varBinds = [ObjectType(ObjectIdentity(x[0]), x[1]).resolveWithMib(\\n;  File "/app/.venv/lib/python3.10/site-packages/pysnmp/smi/rfc1902.py", line 850, in resolveWithMib\\n    self.__args[0].resolveWithMib(mibViewController)\\n;  File "/app/.venv/lib/python3.10/site-packages/pysnmp/smi/rfc1902.py", line 450, in resolveWithMib\\n    self.__indices = rowNode.getIndicesFromInstId(suffix)\\n;  File "/app/.venv/lib/python3.10/site-packages/pysnmp/smi/mibs/SNMPv2-SMI.py", line 1256, in getIndicesFromInstId\\n    raise error.SmiError(\\n;pysnmp.smi.error.SmiError: Excessive instance identifier sub-OIDs left at MibTableRow((1, 3, 6, 1, 4, 1, 2620, 1, 6, 6, 1), None): 0\\ncaused by <class \\\'pysnmp.smi.error.SmiError\\\'>: Excessive instance identifier sub-OIDs left at MibTableRow((1, 3, 6, 1, 4, 1, 2620, 1, 6, 6, 1), None): 0\')')"""

print(msg)